Traceback (most recent call last):
  File "/home/runner/.local/share/virtualenvs/handbook-Tc9B6puV/lib/python3.8/site-packages/jupyter_cache/executors/utils.py", line 51, in single_nb_execution
    executenb(
  File "/home/runner/.local/share/virtualenvs/handbook-Tc9B6puV/lib/python3.8/site-packages/nbclient/client.py", line 1204, in execute
    return NotebookClient(nb=nb, resources=resources, km=km, **kwargs).execute()
  File "/home/runner/.local/share/virtualenvs/handbook-Tc9B6puV/lib/python3.8/site-packages/nbclient/util.py", line 84, in wrapped
    return just_run(coro(*args, **kwargs))
  File "/home/runner/.local/share/virtualenvs/handbook-Tc9B6puV/lib/python3.8/site-packages/nbclient/util.py", line 62, in just_run
    return loop.run_until_complete(coro)
  File "/opt/hostedtoolcache/Python/3.8.18/x64/lib/python3.8/asyncio/base_events.py", line 616, in run_until_complete
    return future.result()
  File "/home/runner/.local/share/virtualenvs/handbook-Tc9B6puV/lib/python3.8/site-packages/nbclient/client.py", line 663, in async_execute
    await self.async_execute_cell(
  File "/home/runner/.local/share/virtualenvs/handbook-Tc9B6puV/lib/python3.8/site-packages/nbclient/client.py", line 965, in async_execute_cell
    await self._check_raise_for_error(cell, cell_index, exec_reply)
  File "/home/runner/.local/share/virtualenvs/handbook-Tc9B6puV/lib/python3.8/site-packages/nbclient/client.py", line 862, in _check_raise_for_error
    raise CellExecutionError.from_cell_and_msg(cell, exec_reply_content)
nbclient.exceptions.CellExecutionError: An error occurred while executing the following cell:
------------------
import asyncio
import time
from asyncio import sleep as asleep


def process(n):
    global start_sync
    time.sleep(n)
    print(f'done process {n} - {time.time()-start_sync:.1f} seconds from start')
    return


def run_processes():
    process(2)
    process(3)
    process(4)
    return


async def aprocess(n):
    global start_async
    await asleep(n)
    print(f'done async process {n} - {time.time()-start_async:.1f} seconds from start')
    return


async def run_aprocesses():
    await asyncio.gather(
        aprocess(2),
        aprocess(3),
        aprocess(4)
    )
    return


if __name__ == '__main__':
    start_sync = time.time()
    run_processes()
    end_sync = time.time()

    print('SYNC TIME: ', f'{end_sync - start_sync:.1f}')

    start_async = time.time()
    asyncio.run(run_aprocesses())
    end_async = time.time()

    print('ASYNC TIME: ', f'{end_async - start_async:.1f}')
------------------

[0;31m---------------------------------------------------------------------------[0m
[0;31mRuntimeError[0m                              Traceback (most recent call last)
Input [0;32mIn [5][0m, in [0;36m<cell line: 36>[0;34m()[0m
[1;32m     41[0m [38;5;28mprint[39m([38;5;124m'[39m[38;5;124mSYNC TIME: [39m[38;5;124m'[39m, [38;5;124mf[39m[38;5;124m'[39m[38;5;132;01m{[39;00mend_sync [38;5;241m-[39m start_sync[38;5;132;01m:[39;00m[38;5;124m.1f[39m[38;5;132;01m}[39;00m[38;5;124m'[39m)
[1;32m     43[0m start_async [38;5;241m=[39m time[38;5;241m.[39mtime()
[0;32m---> 44[0m [43masyncio[49m[38;5;241;43m.[39;49m[43mrun[49m[43m([49m[43mrun_aprocesses[49m[43m([49m[43m)[49m[43m)[49m
[1;32m     45[0m end_async [38;5;241m=[39m time[38;5;241m.[39mtime()
[1;32m     47[0m [38;5;28mprint[39m([38;5;124m'[39m[38;5;124mASYNC TIME: [39m[38;5;124m'[39m, [38;5;124mf[39m[38;5;124m'[39m[38;5;132;01m{[39;00mend_async [38;5;241m-[39m start_async[38;5;132;01m:[39;00m[38;5;124m.1f[39m[38;5;132;01m}[39;00m[38;5;124m'[39m)

File [0;32m/opt/hostedtoolcache/Python/3.8.18/x64/lib/python3.8/asyncio/runners.py:33[0m, in [0;36mrun[0;34m(main, debug)[0m
[1;32m      9[0m [38;5;124;03m"""Execute the coroutine and return the result.[39;00m
[1;32m     10[0m 
[1;32m     11[0m [38;5;124;03mThis function runs the passed coroutine, taking care of[39;00m
[0;32m   (...)[0m
[1;32m     30[0m [38;5;124;03m    asyncio.run(main())[39;00m
[1;32m     31[0m [38;5;124;03m"""[39;00m
[1;32m     32[0m [38;5;28;01mif[39;00m events[38;5;241m.[39m_get_running_loop() [38;5;129;01mis[39;00m [38;5;129;01mnot[39;00m [38;5;28;01mNone[39;00m:
[0;32m---> 33[0m     [38;5;28;01mraise[39;00m [38;5;167;01mRuntimeError[39;00m(
[1;32m     34[0m         [38;5;124m"[39m[38;5;124masyncio.run() cannot be called from a running event loop[39m[38;5;124m"[39m)
[1;32m     36[0m [38;5;28;01mif[39;00m [38;5;129;01mnot[39;00m coroutines[38;5;241m.[39miscoroutine(main):
[1;32m     37[0m     [38;5;28;01mraise[39;00m [38;5;167;01mValueError[39;00m([38;5;124m"[39m[38;5;124ma coroutine was expected, got [39m[38;5;132;01m{!r}[39;00m[38;5;124m"[39m[38;5;241m.[39mformat(main))

[0;31mRuntimeError[0m: asyncio.run() cannot be called from a running event loop
RuntimeError: asyncio.run() cannot be called from a running event loop

