Traceback (most recent call last):
  File "/home/runner/.local/share/virtualenvs/handbook-Tc9B6puV/lib/python3.8/site-packages/jupyter_cache/executors/utils.py", line 51, in single_nb_execution
    executenb(
  File "/home/runner/.local/share/virtualenvs/handbook-Tc9B6puV/lib/python3.8/site-packages/nbclient/client.py", line 1204, in execute
    return NotebookClient(nb=nb, resources=resources, km=km, **kwargs).execute()
  File "/home/runner/.local/share/virtualenvs/handbook-Tc9B6puV/lib/python3.8/site-packages/nbclient/util.py", line 84, in wrapped
    return just_run(coro(*args, **kwargs))
  File "/home/runner/.local/share/virtualenvs/handbook-Tc9B6puV/lib/python3.8/site-packages/nbclient/util.py", line 62, in just_run
    return loop.run_until_complete(coro)
  File "/opt/hostedtoolcache/Python/3.8.18/x64/lib/python3.8/asyncio/base_events.py", line 616, in run_until_complete
    return future.result()
  File "/home/runner/.local/share/virtualenvs/handbook-Tc9B6puV/lib/python3.8/site-packages/nbclient/client.py", line 663, in async_execute
    await self.async_execute_cell(
  File "/home/runner/.local/share/virtualenvs/handbook-Tc9B6puV/lib/python3.8/site-packages/nbclient/client.py", line 965, in async_execute_cell
    await self._check_raise_for_error(cell, cell_index, exec_reply)
  File "/home/runner/.local/share/virtualenvs/handbook-Tc9B6puV/lib/python3.8/site-packages/nbclient/client.py", line 862, in _check_raise_for_error
    raise CellExecutionError.from_cell_and_msg(cell, exec_reply_content)
nbclient.exceptions.CellExecutionError: An error occurred while executing the following cell:
------------------
tasks_to_complete = [some_work('cleaning', 3),
                     some_work('reading', 7),
                     some_work('writing', 10)]
tasks_to_complete.extend([read_statuses()]) # remember to add our reader to task list!

# outside jupyter:
# loop = asyncio.new_event_loop()
# asyncio.set_event_loop(loop)  # Python 3.10+ specific
# loop.run_until_complete(asyncio.gather(*tasks_to_complete))
# loop.close()

results = await asyncio.gather(*tasks_to_complete)
------------------

[0;31m---------------------------------------------------------------------------[0m
[0;31mNameError[0m                                 Traceback (most recent call last)
Input [0;32mIn [3][0m, in [0;36m<cell line: 12>[0;34m()[0m
[1;32m      4[0m tasks_to_complete[38;5;241m.[39mextend([read_statuses()]) [38;5;66;03m# remember to add our reader to task list![39;00m
[1;32m      6[0m [38;5;66;03m# outside jupyter:[39;00m
[1;32m      7[0m [38;5;66;03m# loop = asyncio.new_event_loop()[39;00m
[1;32m      8[0m [38;5;66;03m# asyncio.set_event_loop(loop)  # Python 3.10+ specific[39;00m
[1;32m      9[0m [38;5;66;03m# loop.run_until_complete(asyncio.gather(*tasks_to_complete))[39;00m
[1;32m     10[0m [38;5;66;03m# loop.close()[39;00m
[0;32m---> 12[0m results [38;5;241m=[39m [38;5;28;01mawait[39;00m asyncio[38;5;241m.[39mgather([38;5;241m*[39mtasks_to_complete)

[0;31mNameError[0m: name 'asyncio' is not defined
NameError: name 'asyncio' is not defined

